2024-03-06 20:52:03,410 ERROR Internal Server Error: /news/ E:\projects\np-django\venv\Lib\site-packages\django\utils\log.py (<class 'ValueError'>, ValueError('localtime() cannot be applied to a naive datetime'), <traceback object at 0x000001F54A05C640>)
Traceback (most recent call last):
  File "E:\projects\np-django\venv\Lib\site-packages\django\core\handlers\exception.py", line 55, in inner
    response = get_response(request)
               ^^^^^^^^^^^^^^^^^^^^^
  File "E:\projects\np-django\venv\Lib\site-packages\django\core\handlers\base.py", line 197, in _get_response
    response = wrapped_callback(request, *callback_args, **callback_kwargs)
               ^^^^^^^^^^^^^^^^^^^^^^^^^^^^^^^^^^^^^^^^^^^^^^^^^^^^^^^^^^^^
  File "E:\projects\np-django\venv\Lib\site-packages\django\views\generic\base.py", line 104, in view
    return self.dispatch(request, *args, **kwargs)
           ^^^^^^^^^^^^^^^^^^^^^^^^^^^^^^^^^^^^^^^
  File "E:\projects\np-django\venv\Lib\site-packages\django\views\generic\base.py", line 143, in dispatch
    return handler(request, *args, **kwargs)
           ^^^^^^^^^^^^^^^^^^^^^^^^^^^^^^^^^
  File "E:\projects\np-django\venv\Lib\site-packages\django\views\generic\list.py", line 174, in get
    context = self.get_context_data()
              ^^^^^^^^^^^^^^^^^^^^^^^
  File "E:\projects\np-django\NewsPaper\news\views.py", line 58, in get_context_data
    context['current_time'] = timezone.localtime(timezone.now())
                              ^^^^^^^^^^^^^^^^^^^^^^^^^^^^^^^^^^
  File "E:\projects\np-django\venv\Lib\site-packages\django\utils\timezone.py", line 183, in localtime
    raise ValueError("localtime() cannot be applied to a naive datetime")
ValueError: localtime() cannot be applied to a naive datetime
2024-03-06 20:52:03,417 ERROR "GET /news/ HTTP/1.1" 500 89810 E:\projects\np-django\venv\Lib\site-packages\django\core\servers\basehttp.py None
2024-03-06 20:54:47,826 ERROR Internal Server Error: /news/ E:\projects\np-django\venv\Lib\site-packages\django\utils\log.py (<class 'ValueError'>, ValueError('localtime() cannot be applied to a naive datetime'), <traceback object at 0x000001F548F9A040>)
Traceback (most recent call last):
  File "E:\projects\np-django\venv\Lib\site-packages\django\core\handlers\exception.py", line 55, in inner
    response = get_response(request)
               ^^^^^^^^^^^^^^^^^^^^^
  File "E:\projects\np-django\venv\Lib\site-packages\django\core\handlers\base.py", line 197, in _get_response
    response = wrapped_callback(request, *callback_args, **callback_kwargs)
               ^^^^^^^^^^^^^^^^^^^^^^^^^^^^^^^^^^^^^^^^^^^^^^^^^^^^^^^^^^^^
  File "E:\projects\np-django\venv\Lib\site-packages\django\views\generic\base.py", line 104, in view
    return self.dispatch(request, *args, **kwargs)
           ^^^^^^^^^^^^^^^^^^^^^^^^^^^^^^^^^^^^^^^
  File "E:\projects\np-django\venv\Lib\site-packages\django\views\generic\base.py", line 143, in dispatch
    return handler(request, *args, **kwargs)
           ^^^^^^^^^^^^^^^^^^^^^^^^^^^^^^^^^
  File "E:\projects\np-django\venv\Lib\site-packages\django\views\generic\list.py", line 174, in get
    context = self.get_context_data()
              ^^^^^^^^^^^^^^^^^^^^^^^
  File "E:\projects\np-django\NewsPaper\news\views.py", line 58, in get_context_data
    context['current_time'] = timezone.localtime(timezone.now())
                              ^^^^^^^^^^^^^^^^^^^^^^^^^^^^^^^^^^
  File "E:\projects\np-django\venv\Lib\site-packages\django\utils\timezone.py", line 183, in localtime
    raise ValueError("localtime() cannot be applied to a naive datetime")
ValueError: localtime() cannot be applied to a naive datetime
2024-03-06 20:54:47,830 ERROR "GET /news/ HTTP/1.1" 500 89656 E:\projects\np-django\venv\Lib\site-packages\django\core\servers\basehttp.py None
2024-03-06 20:56:43,573 ERROR Internal Server Error: /news/ E:\projects\np-django\venv\Lib\site-packages\django\utils\log.py (<class 'django.template.exceptions.TemplateSyntaxError'>, TemplateSyntaxError("Invalid block tag on line 82: 'get_current_timezone'. Did you forget to register or load this tag?"), <traceback object at 0x0000025A7CDA2040>)
Traceback (most recent call last):
  File "E:\projects\np-django\venv\Lib\site-packages\django\template\base.py", line 502, in parse
    compile_func = self.tags[command]
                   ~~~~~~~~~^^^^^^^^^
KeyError: 'get_current_timezone'

During handling of the above exception, another exception occurred:

Traceback (most recent call last):
  File "E:\projects\np-django\venv\Lib\site-packages\django\core\handlers\exception.py", line 55, in inner
    response = get_response(request)
               ^^^^^^^^^^^^^^^^^^^^^
  File "E:\projects\np-django\venv\Lib\site-packages\django\core\handlers\base.py", line 220, in _get_response
    response = response.render()
               ^^^^^^^^^^^^^^^^^
  File "E:\projects\np-django\venv\Lib\site-packages\django\template\response.py", line 114, in render
    self.content = self.rendered_content
                   ^^^^^^^^^^^^^^^^^^^^^
  File "E:\projects\np-django\venv\Lib\site-packages\django\template\response.py", line 92, in rendered_content
    return template.render(context, self._request)
           ^^^^^^^^^^^^^^^^^^^^^^^^^^^^^^^^^^^^^^^
  File "E:\projects\np-django\venv\Lib\site-packages\django\template\backends\django.py", line 61, in render
    return self.template.render(context)
           ^^^^^^^^^^^^^^^^^^^^^^^^^^^^^
  File "E:\projects\np-django\venv\Lib\site-packages\django\template\base.py", line 171, in render
    return self._render(context)
           ^^^^^^^^^^^^^^^^^^^^^
  File "E:\projects\np-django\venv\Lib\site-packages\django\template\base.py", line 163, in _render
    return self.nodelist.render(context)
           ^^^^^^^^^^^^^^^^^^^^^^^^^^^^^
  File "E:\projects\np-django\venv\Lib\site-packages\django\template\base.py", line 1000, in render
    return SafeString("".join([node.render_annotated(context) for node in self]))
                              ^^^^^^^^^^^^^^^^^^^^^^^^^^^^^^^^^^^^^^^^^^^^^^^^^
  File "E:\projects\np-django\venv\Lib\site-packages\django\template\base.py", line 1000, in <listcomp>
    return SafeString("".join([node.render_annotated(context) for node in self]))
                               ^^^^^^^^^^^^^^^^^^^^^^^^^^^^^^
  File "E:\projects\np-django\venv\Lib\site-packages\django\template\base.py", line 961, in render_annotated
    return self.render(context)
           ^^^^^^^^^^^^^^^^^^^^
  File "E:\projects\np-django\venv\Lib\site-packages\django\template\loader_tags.py", line 134, in render
    compiled_parent = self.get_parent(context)
                      ^^^^^^^^^^^^^^^^^^^^^^^^
  File "E:\projects\np-django\venv\Lib\site-packages\django\template\loader_tags.py", line 131, in get_parent
    return self.find_template(parent, context)
           ^^^^^^^^^^^^^^^^^^^^^^^^^^^^^^^^^^^
  File "E:\projects\np-django\venv\Lib\site-packages\django\template\loader_tags.py", line 109, in find_template
    template, origin = context.template.engine.find_template(
                       ^^^^^^^^^^^^^^^^^^^^^^^^^^^^^^^^^^^^^^
  File "E:\projects\np-django\venv\Lib\site-packages\django\template\engine.py", line 157, in find_template
    template = loader.get_template(name, skip=skip)
               ^^^^^^^^^^^^^^^^^^^^^^^^^^^^^^^^^^^^
  File "E:\projects\np-django\venv\Lib\site-packages\django\template\loaders\cached.py", line 57, in get_template
    template = super().get_template(template_name, skip)
               ^^^^^^^^^^^^^^^^^^^^^^^^^^^^^^^^^^^^^^^^^
  File "E:\projects\np-django\venv\Lib\site-packages\django\template\loaders\base.py", line 28, in get_template
    return Template(
           ^^^^^^^^^
  File "E:\projects\np-django\venv\Lib\site-packages\django\template\base.py", line 154, in __init__
    self.nodelist = self.compile_nodelist()
                    ^^^^^^^^^^^^^^^^^^^^^^^
  File "E:\projects\np-django\venv\Lib\site-packages\django\template\base.py", line 196, in compile_nodelist
    return parser.parse()
           ^^^^^^^^^^^^^^
  File "E:\projects\np-django\venv\Lib\site-packages\django\template\base.py", line 504, in parse
    self.invalid_block_tag(token, command, parse_until)
  File "E:\projects\np-django\venv\Lib\site-packages\django\template\base.py", line 565, in invalid_block_tag
    raise self.error(
django.template.exceptions.TemplateSyntaxError: Invalid block tag on line 82: 'get_current_timezone'. Did you forget to register or load this tag?
2024-03-06 20:56:43,582 ERROR "GET /news/ HTTP/1.1" 500 197209 E:\projects\np-django\venv\Lib\site-packages\django\core\servers\basehttp.py None
2024-03-06 21:18:42,525 ERROR Internal Server Error: /news/ E:\projects\np-django\venv\Lib\site-packages\django\utils\log.py (<class 'NameError'>, NameError("name 'MyModel' is not defined"), <traceback object at 0x000001B842C5B040>)
Traceback (most recent call last):
  File "E:\projects\np-django\venv\Lib\site-packages\django\core\handlers\exception.py", line 55, in inner
    response = get_response(request)
               ^^^^^^^^^^^^^^^^^^^^^
  File "E:\projects\np-django\venv\Lib\site-packages\django\core\handlers\base.py", line 197, in _get_response
    response = wrapped_callback(request, *callback_args, **callback_kwargs)
               ^^^^^^^^^^^^^^^^^^^^^^^^^^^^^^^^^^^^^^^^^^^^^^^^^^^^^^^^^^^^
  File "E:\projects\np-django\venv\Lib\site-packages\django\views\generic\base.py", line 104, in view
    return self.dispatch(request, *args, **kwargs)
           ^^^^^^^^^^^^^^^^^^^^^^^^^^^^^^^^^^^^^^^
  File "E:\projects\np-django\venv\Lib\site-packages\django\views\generic\base.py", line 143, in dispatch
    return handler(request, *args, **kwargs)
           ^^^^^^^^^^^^^^^^^^^^^^^^^^^^^^^^^
  File "E:\projects\np-django\NewsPaper\news\views.py", line 64, in get
    models = MyModel.objects.all()
             ^^^^^^^
NameError: name 'MyModel' is not defined
2024-03-06 21:18:42,530 ERROR "GET /news/ HTTP/1.1" 500 78410 E:\projects\np-django\venv\Lib\site-packages\django\core\servers\basehttp.py None
2024-03-06 21:19:03,040 ERROR Internal Server Error: /news/ E:\projects\np-django\venv\Lib\site-packages\django\utils\log.py (<class 'ValueError'>, ValueError('localtime() cannot be applied to a naive datetime'), <traceback object at 0x00000147BC4B1D00>)
Traceback (most recent call last):
  File "E:\projects\np-django\venv\Lib\site-packages\django\core\handlers\exception.py", line 55, in inner
    response = get_response(request)
               ^^^^^^^^^^^^^^^^^^^^^
  File "E:\projects\np-django\venv\Lib\site-packages\django\core\handlers\base.py", line 197, in _get_response
    response = wrapped_callback(request, *callback_args, **callback_kwargs)
               ^^^^^^^^^^^^^^^^^^^^^^^^^^^^^^^^^^^^^^^^^^^^^^^^^^^^^^^^^^^^
  File "E:\projects\np-django\venv\Lib\site-packages\django\views\generic\base.py", line 104, in view
    return self.dispatch(request, *args, **kwargs)
           ^^^^^^^^^^^^^^^^^^^^^^^^^^^^^^^^^^^^^^^
  File "E:\projects\np-django\venv\Lib\site-packages\django\views\generic\base.py", line 143, in dispatch
    return handler(request, *args, **kwargs)
           ^^^^^^^^^^^^^^^^^^^^^^^^^^^^^^^^^
  File "E:\projects\np-django\NewsPaper\news\views.py", line 65, in get
    'current_time': timezone.localtime(timezone.now()),
                    ^^^^^^^^^^^^^^^^^^^^^^^^^^^^^^^^^^
  File "E:\projects\np-django\venv\Lib\site-packages\django\utils\timezone.py", line 183, in localtime
    raise ValueError("localtime() cannot be applied to a naive datetime")
ValueError: localtime() cannot be applied to a naive datetime
2024-03-06 21:19:03,040 ERROR "GET /news/ HTTP/1.1" 500 82596 E:\projects\np-django\venv\Lib\site-packages\django\core\servers\basehttp.py None
2024-03-06 21:28:40,070 ERROR Internal Server Error: /news/ E:\projects\np-django\venv\Lib\site-packages\django\utils\log.py (<class 'django.template.exceptions.TemplateDoesNotExist'>, TemplateDoesNotExist('index.html'), <traceback object at 0x000001EADF4DBAC0>)
Traceback (most recent call last):
  File "E:\projects\np-django\venv\Lib\site-packages\django\core\handlers\exception.py", line 55, in inner
    response = get_response(request)
               ^^^^^^^^^^^^^^^^^^^^^
  File "E:\projects\np-django\venv\Lib\site-packages\django\core\handlers\base.py", line 197, in _get_response
    response = wrapped_callback(request, *callback_args, **callback_kwargs)
               ^^^^^^^^^^^^^^^^^^^^^^^^^^^^^^^^^^^^^^^^^^^^^^^^^^^^^^^^^^^^
  File "E:\projects\np-django\venv\Lib\site-packages\django\views\generic\base.py", line 104, in view
    return self.dispatch(request, *args, **kwargs)
           ^^^^^^^^^^^^^^^^^^^^^^^^^^^^^^^^^^^^^^^
  File "E:\projects\np-django\venv\Lib\site-packages\django\views\generic\base.py", line 143, in dispatch
    return handler(request, *args, **kwargs)
           ^^^^^^^^^^^^^^^^^^^^^^^^^^^^^^^^^
  File "E:\projects\np-django\NewsPaper\news\views.py", line 69, in get
    return HttpResponse(render(request, 'index.html', context))
                        ^^^^^^^^^^^^^^^^^^^^^^^^^^^^^^^^^^^^^^
  File "E:\projects\np-django\venv\Lib\site-packages\django\shortcuts.py", line 24, in render
    content = loader.render_to_string(template_name, context, request, using=using)
              ^^^^^^^^^^^^^^^^^^^^^^^^^^^^^^^^^^^^^^^^^^^^^^^^^^^^^^^^^^^^^^^^^^^^^
  File "E:\projects\np-django\venv\Lib\site-packages\django\template\loader.py", line 61, in render_to_string
    template = get_template(template_name, using=using)
               ^^^^^^^^^^^^^^^^^^^^^^^^^^^^^^^^^^^^^^^^
  File "E:\projects\np-django\venv\Lib\site-packages\django\template\loader.py", line 19, in get_template
    raise TemplateDoesNotExist(template_name, chain=chain)
django.template.exceptions.TemplateDoesNotExist: index.html
2024-03-06 21:28:40,221 ERROR Internal Server Error: /news/ E:\projects\np-django\venv\Lib\site-packages\django\utils\log.py (<class 'django.template.exceptions.TemplateDoesNotExist'>, TemplateDoesNotExist('index.html'), <traceback object at 0x000001EADF4DCE80>)
Traceback (most recent call last):
  File "E:\projects\np-django\venv\Lib\site-packages\django\core\handlers\exception.py", line 55, in inner
    response = get_response(request)
               ^^^^^^^^^^^^^^^^^^^^^
  File "E:\projects\np-django\venv\Lib\site-packages\django\core\handlers\base.py", line 197, in _get_response
    response = wrapped_callback(request, *callback_args, **callback_kwargs)
               ^^^^^^^^^^^^^^^^^^^^^^^^^^^^^^^^^^^^^^^^^^^^^^^^^^^^^^^^^^^^
  File "E:\projects\np-django\venv\Lib\site-packages\django\views\generic\base.py", line 104, in view
    return self.dispatch(request, *args, **kwargs)
           ^^^^^^^^^^^^^^^^^^^^^^^^^^^^^^^^^^^^^^^
  File "E:\projects\np-django\venv\Lib\site-packages\django\views\generic\base.py", line 143, in dispatch
    return handler(request, *args, **kwargs)
           ^^^^^^^^^^^^^^^^^^^^^^^^^^^^^^^^^
  File "E:\projects\np-django\NewsPaper\news\views.py", line 69, in get
    return HttpResponse(render(request, 'index.html', context))
                        ^^^^^^^^^^^^^^^^^^^^^^^^^^^^^^^^^^^^^^
  File "E:\projects\np-django\venv\Lib\site-packages\django\shortcuts.py", line 24, in render
    content = loader.render_to_string(template_name, context, request, using=using)
              ^^^^^^^^^^^^^^^^^^^^^^^^^^^^^^^^^^^^^^^^^^^^^^^^^^^^^^^^^^^^^^^^^^^^^
  File "E:\projects\np-django\venv\Lib\site-packages\django\template\loader.py", line 61, in render_to_string
    template = get_template(template_name, using=using)
               ^^^^^^^^^^^^^^^^^^^^^^^^^^^^^^^^^^^^^^^^
  File "E:\projects\np-django\venv\Lib\site-packages\django\template\loader.py", line 19, in get_template
    raise TemplateDoesNotExist(template_name, chain=chain)
django.template.exceptions.TemplateDoesNotExist: index.html
2024-03-06 21:28:40,221 ERROR "GET /news/ HTTP/1.1" 500 110053 E:\projects\np-django\venv\Lib\site-packages\django\core\servers\basehttp.py None
2024-03-06 21:28:56,303 ERROR Internal Server Error: /news/ E:\projects\np-django\venv\Lib\site-packages\django\utils\log.py (<class 'django.template.exceptions.TemplateDoesNotExist'>, TemplateDoesNotExist('default.html'), <traceback object at 0x000001A511B3FF00>)
Traceback (most recent call last):
  File "E:\projects\np-django\venv\Lib\site-packages\django\core\handlers\exception.py", line 55, in inner
    response = get_response(request)
               ^^^^^^^^^^^^^^^^^^^^^
  File "E:\projects\np-django\venv\Lib\site-packages\django\core\handlers\base.py", line 197, in _get_response
    response = wrapped_callback(request, *callback_args, **callback_kwargs)
               ^^^^^^^^^^^^^^^^^^^^^^^^^^^^^^^^^^^^^^^^^^^^^^^^^^^^^^^^^^^^
  File "E:\projects\np-django\venv\Lib\site-packages\django\views\generic\base.py", line 104, in view
    return self.dispatch(request, *args, **kwargs)
           ^^^^^^^^^^^^^^^^^^^^^^^^^^^^^^^^^^^^^^^
  File "E:\projects\np-django\venv\Lib\site-packages\django\views\generic\base.py", line 143, in dispatch
    return handler(request, *args, **kwargs)
           ^^^^^^^^^^^^^^^^^^^^^^^^^^^^^^^^^
  File "E:\projects\np-django\NewsPaper\news\views.py", line 69, in get
    return HttpResponse(render(request, 'default.html', context))
                        ^^^^^^^^^^^^^^^^^^^^^^^^^^^^^^^^^^^^^^^^
  File "E:\projects\np-django\venv\Lib\site-packages\django\shortcuts.py", line 24, in render
    content = loader.render_to_string(template_name, context, request, using=using)
              ^^^^^^^^^^^^^^^^^^^^^^^^^^^^^^^^^^^^^^^^^^^^^^^^^^^^^^^^^^^^^^^^^^^^^
  File "E:\projects\np-django\venv\Lib\site-packages\django\template\loader.py", line 61, in render_to_string
    template = get_template(template_name, using=using)
               ^^^^^^^^^^^^^^^^^^^^^^^^^^^^^^^^^^^^^^^^
  File "E:\projects\np-django\venv\Lib\site-packages\django\template\loader.py", line 19, in get_template
    raise TemplateDoesNotExist(template_name, chain=chain)
django.template.exceptions.TemplateDoesNotExist: default.html
2024-03-06 21:28:56,309 ERROR "GET /news/ HTTP/1.1" 500 110097 E:\projects\np-django\venv\Lib\site-packages\django\core\servers\basehttp.py None
2024-03-06 21:39:09,239 ERROR Internal Server Error: /news/ E:\projects\np-django\venv\Lib\site-packages\django\utils\log.py (<class 'ValueError'>, ValueError('localtime() cannot be applied to a naive datetime'), <traceback object at 0x000002547C02F600>)
Traceback (most recent call last):
  File "E:\projects\np-django\venv\Lib\site-packages\django\core\handlers\exception.py", line 55, in inner
    response = get_response(request)
               ^^^^^^^^^^^^^^^^^^^^^
  File "E:\projects\np-django\venv\Lib\site-packages\django\core\handlers\base.py", line 197, in _get_response
    response = wrapped_callback(request, *callback_args, **callback_kwargs)
               ^^^^^^^^^^^^^^^^^^^^^^^^^^^^^^^^^^^^^^^^^^^^^^^^^^^^^^^^^^^^
  File "E:\projects\np-django\venv\Lib\site-packages\django\views\generic\base.py", line 104, in view
    return self.dispatch(request, *args, **kwargs)
           ^^^^^^^^^^^^^^^^^^^^^^^^^^^^^^^^^^^^^^^
  File "E:\projects\np-django\venv\Lib\site-packages\django\views\generic\base.py", line 143, in dispatch
    return handler(request, *args, **kwargs)
           ^^^^^^^^^^^^^^^^^^^^^^^^^^^^^^^^^
  File "E:\projects\np-django\NewsPaper\news\views.py", line 64, in get
    'current_time': timezone.localtime(timezone.now()),
                    ^^^^^^^^^^^^^^^^^^^^^^^^^^^^^^^^^^
  File "E:\projects\np-django\venv\Lib\site-packages\django\utils\timezone.py", line 183, in localtime
    raise ValueError("localtime() cannot be applied to a naive datetime")
ValueError: localtime() cannot be applied to a naive datetime
2024-03-06 21:39:09,250 ERROR "GET /news/ HTTP/1.1" 500 82536 E:\projects\np-django\venv\Lib\site-packages\django\core\servers\basehttp.py None
2024-03-06 21:45:27,491 ERROR Internal Server Error: /news/ E:\projects\np-django\venv\Lib\site-packages\django\utils\log.py (<class 'ValueError'>, ValueError('localtime() cannot be applied to a naive datetime'), <traceback object at 0x000001B876452C40>)
Traceback (most recent call last):
  File "E:\projects\np-django\venv\Lib\site-packages\django\core\handlers\exception.py", line 55, in inner
    response = get_response(request)
               ^^^^^^^^^^^^^^^^^^^^^
  File "E:\projects\np-django\venv\Lib\site-packages\django\core\handlers\base.py", line 197, in _get_response
    response = wrapped_callback(request, *callback_args, **callback_kwargs)
               ^^^^^^^^^^^^^^^^^^^^^^^^^^^^^^^^^^^^^^^^^^^^^^^^^^^^^^^^^^^^
  File "E:\projects\np-django\venv\Lib\site-packages\django\views\generic\base.py", line 104, in view
    return self.dispatch(request, *args, **kwargs)
           ^^^^^^^^^^^^^^^^^^^^^^^^^^^^^^^^^^^^^^^
  File "E:\projects\np-django\venv\Lib\site-packages\django\views\generic\base.py", line 143, in dispatch
    return handler(request, *args, **kwargs)
           ^^^^^^^^^^^^^^^^^^^^^^^^^^^^^^^^^
  File "E:\projects\np-django\NewsPaper\news\views.py", line 64, in get
    'current_time': timezone.localtime(timezone.now()),
                    ^^^^^^^^^^^^^^^^^^^^^^^^^^^^^^^^^^
  File "E:\projects\np-django\venv\Lib\site-packages\django\utils\timezone.py", line 183, in localtime
    raise ValueError("localtime() cannot be applied to a naive datetime")
ValueError: localtime() cannot be applied to a naive datetime
2024-03-06 21:45:27,500 ERROR "GET /news/ HTTP/1.1" 500 82545 E:\projects\np-django\venv\Lib\site-packages\django\core\servers\basehttp.py None
2024-03-06 21:45:29,240 ERROR Internal Server Error: /news/ E:\projects\np-django\venv\Lib\site-packages\django\utils\log.py (<class 'ValueError'>, ValueError('localtime() cannot be applied to a naive datetime'), <traceback object at 0x000001B876416900>)
Traceback (most recent call last):
  File "E:\projects\np-django\venv\Lib\site-packages\django\core\handlers\exception.py", line 55, in inner
    response = get_response(request)
               ^^^^^^^^^^^^^^^^^^^^^
  File "E:\projects\np-django\venv\Lib\site-packages\django\core\handlers\base.py", line 197, in _get_response
    response = wrapped_callback(request, *callback_args, **callback_kwargs)
               ^^^^^^^^^^^^^^^^^^^^^^^^^^^^^^^^^^^^^^^^^^^^^^^^^^^^^^^^^^^^
  File "E:\projects\np-django\venv\Lib\site-packages\django\views\generic\base.py", line 104, in view
    return self.dispatch(request, *args, **kwargs)
           ^^^^^^^^^^^^^^^^^^^^^^^^^^^^^^^^^^^^^^^
  File "E:\projects\np-django\venv\Lib\site-packages\django\views\generic\base.py", line 143, in dispatch
    return handler(request, *args, **kwargs)
           ^^^^^^^^^^^^^^^^^^^^^^^^^^^^^^^^^
  File "E:\projects\np-django\NewsPaper\news\views.py", line 64, in get
    'current_time': timezone.localtime(timezone.now()),
                    ^^^^^^^^^^^^^^^^^^^^^^^^^^^^^^^^^^
  File "E:\projects\np-django\venv\Lib\site-packages\django\utils\timezone.py", line 183, in localtime
    raise ValueError("localtime() cannot be applied to a naive datetime")
ValueError: localtime() cannot be applied to a naive datetime
2024-03-06 21:45:29,240 ERROR "GET /news/ HTTP/1.1" 500 82545 E:\projects\np-django\venv\Lib\site-packages\django\core\servers\basehttp.py None
2024-03-06 21:45:52,110 ERROR Internal Server Error: /news/ E:\projects\np-django\venv\Lib\site-packages\django\utils\log.py (<class 'django.urls.exceptions.NoReverseMatch'>, NoReverseMatch("Reverse for 'set_timezone' not found. 'set_timezone' is not a valid view function or pattern name."), <traceback object at 0x000002975810B9C0>)
Traceback (most recent call last):
  File "E:\projects\np-django\venv\Lib\site-packages\django\core\handlers\exception.py", line 55, in inner
    response = get_response(request)
               ^^^^^^^^^^^^^^^^^^^^^
  File "E:\projects\np-django\venv\Lib\site-packages\django\core\handlers\base.py", line 220, in _get_response
    response = response.render()
               ^^^^^^^^^^^^^^^^^
  File "E:\projects\np-django\venv\Lib\site-packages\django\template\response.py", line 114, in render
    self.content = self.rendered_content
                   ^^^^^^^^^^^^^^^^^^^^^
  File "E:\projects\np-django\venv\Lib\site-packages\django\template\response.py", line 92, in rendered_content
    return template.render(context, self._request)
           ^^^^^^^^^^^^^^^^^^^^^^^^^^^^^^^^^^^^^^^
  File "E:\projects\np-django\venv\Lib\site-packages\django\template\backends\django.py", line 61, in render
    return self.template.render(context)
           ^^^^^^^^^^^^^^^^^^^^^^^^^^^^^
  File "E:\projects\np-django\venv\Lib\site-packages\django\template\base.py", line 171, in render
    return self._render(context)
           ^^^^^^^^^^^^^^^^^^^^^
  File "E:\projects\np-django\venv\Lib\site-packages\django\template\base.py", line 163, in _render
    return self.nodelist.render(context)
           ^^^^^^^^^^^^^^^^^^^^^^^^^^^^^
  File "E:\projects\np-django\venv\Lib\site-packages\django\template\base.py", line 1000, in render
    return SafeString("".join([node.render_annotated(context) for node in self]))
                              ^^^^^^^^^^^^^^^^^^^^^^^^^^^^^^^^^^^^^^^^^^^^^^^^^
  File "E:\projects\np-django\venv\Lib\site-packages\django\template\base.py", line 1000, in <listcomp>
    return SafeString("".join([node.render_annotated(context) for node in self]))
                               ^^^^^^^^^^^^^^^^^^^^^^^^^^^^^^
  File "E:\projects\np-django\venv\Lib\site-packages\django\template\base.py", line 961, in render_annotated
    return self.render(context)
           ^^^^^^^^^^^^^^^^^^^^
  File "E:\projects\np-django\venv\Lib\site-packages\django\template\loader_tags.py", line 159, in render
    return compiled_parent._render(context)
           ^^^^^^^^^^^^^^^^^^^^^^^^^^^^^^^^
  File "E:\projects\np-django\venv\Lib\site-packages\django\template\base.py", line 163, in _render
    return self.nodelist.render(context)
           ^^^^^^^^^^^^^^^^^^^^^^^^^^^^^
  File "E:\projects\np-django\venv\Lib\site-packages\django\template\base.py", line 1000, in render
    return SafeString("".join([node.render_annotated(context) for node in self]))
                              ^^^^^^^^^^^^^^^^^^^^^^^^^^^^^^^^^^^^^^^^^^^^^^^^^
  File "E:\projects\np-django\venv\Lib\site-packages\django\template\base.py", line 1000, in <listcomp>
    return SafeString("".join([node.render_annotated(context) for node in self]))
                               ^^^^^^^^^^^^^^^^^^^^^^^^^^^^^^
  File "E:\projects\np-django\venv\Lib\site-packages\django\template\base.py", line 961, in render_annotated
    return self.render(context)
           ^^^^^^^^^^^^^^^^^^^^
  File "E:\projects\np-django\venv\Lib\site-packages\django\template\defaulttags.py", line 478, in render
    url = reverse(view_name, args=args, kwargs=kwargs, current_app=current_app)
          ^^^^^^^^^^^^^^^^^^^^^^^^^^^^^^^^^^^^^^^^^^^^^^^^^^^^^^^^^^^^^^^^^^^^^
  File "E:\projects\np-django\venv\Lib\site-packages\django\urls\base.py", line 88, in reverse
    return resolver._reverse_with_prefix(view, prefix, *args, **kwargs)
           ^^^^^^^^^^^^^^^^^^^^^^^^^^^^^^^^^^^^^^^^^^^^^^^^^^^^^^^^^^^^
  File "E:\projects\np-django\venv\Lib\site-packages\django\urls\resolvers.py", line 848, in _reverse_with_prefix
    raise NoReverseMatch(msg)
django.urls.exceptions.NoReverseMatch: Reverse for 'set_timezone' not found. 'set_timezone' is not a valid view function or pattern name.
2024-03-06 21:45:52,110 ERROR "GET /news/ HTTP/1.1" 500 172082 E:\projects\np-django\venv\Lib\site-packages\django\core\servers\basehttp.py None
2024-03-06 21:46:16,339 ERROR Internal Server Error: /news/ E:\projects\np-django\venv\Lib\site-packages\django\utils\log.py (<class 'django.urls.exceptions.NoReverseMatch'>, NoReverseMatch("Reverse for 'set_timezone' not found. 'set_timezone' is not a valid view function or pattern name."), <traceback object at 0x000002433B651540>)
Traceback (most recent call last):
  File "E:\projects\np-django\venv\Lib\site-packages\django\core\handlers\exception.py", line 55, in inner
    response = get_response(request)
               ^^^^^^^^^^^^^^^^^^^^^
  File "E:\projects\np-django\venv\Lib\site-packages\django\core\handlers\base.py", line 220, in _get_response
    response = response.render()
               ^^^^^^^^^^^^^^^^^
  File "E:\projects\np-django\venv\Lib\site-packages\django\template\response.py", line 114, in render
    self.content = self.rendered_content
                   ^^^^^^^^^^^^^^^^^^^^^
  File "E:\projects\np-django\venv\Lib\site-packages\django\template\response.py", line 92, in rendered_content
    return template.render(context, self._request)
           ^^^^^^^^^^^^^^^^^^^^^^^^^^^^^^^^^^^^^^^
  File "E:\projects\np-django\venv\Lib\site-packages\django\template\backends\django.py", line 61, in render
    return self.template.render(context)
           ^^^^^^^^^^^^^^^^^^^^^^^^^^^^^
  File "E:\projects\np-django\venv\Lib\site-packages\django\template\base.py", line 171, in render
    return self._render(context)
           ^^^^^^^^^^^^^^^^^^^^^
  File "E:\projects\np-django\venv\Lib\site-packages\django\template\base.py", line 163, in _render
    return self.nodelist.render(context)
           ^^^^^^^^^^^^^^^^^^^^^^^^^^^^^
  File "E:\projects\np-django\venv\Lib\site-packages\django\template\base.py", line 1000, in render
    return SafeString("".join([node.render_annotated(context) for node in self]))
                              ^^^^^^^^^^^^^^^^^^^^^^^^^^^^^^^^^^^^^^^^^^^^^^^^^
  File "E:\projects\np-django\venv\Lib\site-packages\django\template\base.py", line 1000, in <listcomp>
    return SafeString("".join([node.render_annotated(context) for node in self]))
                               ^^^^^^^^^^^^^^^^^^^^^^^^^^^^^^
  File "E:\projects\np-django\venv\Lib\site-packages\django\template\base.py", line 961, in render_annotated
    return self.render(context)
           ^^^^^^^^^^^^^^^^^^^^
  File "E:\projects\np-django\venv\Lib\site-packages\django\template\loader_tags.py", line 159, in render
    return compiled_parent._render(context)
           ^^^^^^^^^^^^^^^^^^^^^^^^^^^^^^^^
  File "E:\projects\np-django\venv\Lib\site-packages\django\template\base.py", line 163, in _render
    return self.nodelist.render(context)
           ^^^^^^^^^^^^^^^^^^^^^^^^^^^^^
  File "E:\projects\np-django\venv\Lib\site-packages\django\template\base.py", line 1000, in render
    return SafeString("".join([node.render_annotated(context) for node in self]))
                              ^^^^^^^^^^^^^^^^^^^^^^^^^^^^^^^^^^^^^^^^^^^^^^^^^
  File "E:\projects\np-django\venv\Lib\site-packages\django\template\base.py", line 1000, in <listcomp>
    return SafeString("".join([node.render_annotated(context) for node in self]))
                               ^^^^^^^^^^^^^^^^^^^^^^^^^^^^^^
  File "E:\projects\np-django\venv\Lib\site-packages\django\template\base.py", line 961, in render_annotated
    return self.render(context)
           ^^^^^^^^^^^^^^^^^^^^
  File "E:\projects\np-django\venv\Lib\site-packages\django\template\defaulttags.py", line 478, in render
    url = reverse(view_name, args=args, kwargs=kwargs, current_app=current_app)
          ^^^^^^^^^^^^^^^^^^^^^^^^^^^^^^^^^^^^^^^^^^^^^^^^^^^^^^^^^^^^^^^^^^^^^
  File "E:\projects\np-django\venv\Lib\site-packages\django\urls\base.py", line 88, in reverse
    return resolver._reverse_with_prefix(view, prefix, *args, **kwargs)
           ^^^^^^^^^^^^^^^^^^^^^^^^^^^^^^^^^^^^^^^^^^^^^^^^^^^^^^^^^^^^
  File "E:\projects\np-django\venv\Lib\site-packages\django\urls\resolvers.py", line 848, in _reverse_with_prefix
    raise NoReverseMatch(msg)
django.urls.exceptions.NoReverseMatch: Reverse for 'set_timezone' not found. 'set_timezone' is not a valid view function or pattern name.
2024-03-06 21:46:16,356 ERROR "GET /news/ HTTP/1.1" 500 172082 E:\projects\np-django\venv\Lib\site-packages\django\core\servers\basehttp.py None
2024-03-06 21:48:49,189 ERROR Internal Server Error: /news/ E:\projects\np-django\venv\Lib\site-packages\django\utils\log.py (<class 'django.urls.exceptions.NoReverseMatch'>, NoReverseMatch("Reverse for 'PostList.set_timezone' not found. 'PostList.set_timezone' is not a valid view function or pattern name."), <traceback object at 0x000002433CA21540>)
Traceback (most recent call last):
  File "E:\projects\np-django\venv\Lib\site-packages\django\core\handlers\exception.py", line 55, in inner
    response = get_response(request)
               ^^^^^^^^^^^^^^^^^^^^^
  File "E:\projects\np-django\venv\Lib\site-packages\django\core\handlers\base.py", line 220, in _get_response
    response = response.render()
               ^^^^^^^^^^^^^^^^^
  File "E:\projects\np-django\venv\Lib\site-packages\django\template\response.py", line 114, in render
    self.content = self.rendered_content
                   ^^^^^^^^^^^^^^^^^^^^^
  File "E:\projects\np-django\venv\Lib\site-packages\django\template\response.py", line 92, in rendered_content
    return template.render(context, self._request)
           ^^^^^^^^^^^^^^^^^^^^^^^^^^^^^^^^^^^^^^^
  File "E:\projects\np-django\venv\Lib\site-packages\django\template\backends\django.py", line 61, in render
    return self.template.render(context)
           ^^^^^^^^^^^^^^^^^^^^^^^^^^^^^
  File "E:\projects\np-django\venv\Lib\site-packages\django\template\base.py", line 171, in render
    return self._render(context)
           ^^^^^^^^^^^^^^^^^^^^^
  File "E:\projects\np-django\venv\Lib\site-packages\django\template\base.py", line 163, in _render
    return self.nodelist.render(context)
           ^^^^^^^^^^^^^^^^^^^^^^^^^^^^^
  File "E:\projects\np-django\venv\Lib\site-packages\django\template\base.py", line 1000, in render
    return SafeString("".join([node.render_annotated(context) for node in self]))
                              ^^^^^^^^^^^^^^^^^^^^^^^^^^^^^^^^^^^^^^^^^^^^^^^^^
  File "E:\projects\np-django\venv\Lib\site-packages\django\template\base.py", line 1000, in <listcomp>
    return SafeString("".join([node.render_annotated(context) for node in self]))
                               ^^^^^^^^^^^^^^^^^^^^^^^^^^^^^^
  File "E:\projects\np-django\venv\Lib\site-packages\django\template\base.py", line 961, in render_annotated
    return self.render(context)
           ^^^^^^^^^^^^^^^^^^^^
  File "E:\projects\np-django\venv\Lib\site-packages\django\template\loader_tags.py", line 159, in render
    return compiled_parent._render(context)
           ^^^^^^^^^^^^^^^^^^^^^^^^^^^^^^^^
  File "E:\projects\np-django\venv\Lib\site-packages\django\template\base.py", line 163, in _render
    return self.nodelist.render(context)
           ^^^^^^^^^^^^^^^^^^^^^^^^^^^^^
  File "E:\projects\np-django\venv\Lib\site-packages\django\template\base.py", line 1000, in render
    return SafeString("".join([node.render_annotated(context) for node in self]))
                              ^^^^^^^^^^^^^^^^^^^^^^^^^^^^^^^^^^^^^^^^^^^^^^^^^
  File "E:\projects\np-django\venv\Lib\site-packages\django\template\base.py", line 1000, in <listcomp>
    return SafeString("".join([node.render_annotated(context) for node in self]))
                               ^^^^^^^^^^^^^^^^^^^^^^^^^^^^^^
  File "E:\projects\np-django\venv\Lib\site-packages\django\template\base.py", line 961, in render_annotated
    return self.render(context)
           ^^^^^^^^^^^^^^^^^^^^
  File "E:\projects\np-django\venv\Lib\site-packages\django\template\defaulttags.py", line 478, in render
    url = reverse(view_name, args=args, kwargs=kwargs, current_app=current_app)
          ^^^^^^^^^^^^^^^^^^^^^^^^^^^^^^^^^^^^^^^^^^^^^^^^^^^^^^^^^^^^^^^^^^^^^
  File "E:\projects\np-django\venv\Lib\site-packages\django\urls\base.py", line 88, in reverse
    return resolver._reverse_with_prefix(view, prefix, *args, **kwargs)
           ^^^^^^^^^^^^^^^^^^^^^^^^^^^^^^^^^^^^^^^^^^^^^^^^^^^^^^^^^^^^
  File "E:\projects\np-django\venv\Lib\site-packages\django\urls\resolvers.py", line 848, in _reverse_with_prefix
    raise NoReverseMatch(msg)
django.urls.exceptions.NoReverseMatch: Reverse for 'PostList.set_timezone' not found. 'PostList.set_timezone' is not a valid view function or pattern name.
2024-03-06 21:48:49,197 ERROR "GET /news/ HTTP/1.1" 500 172307 E:\projects\np-django\venv\Lib\site-packages\django\core\servers\basehttp.py None
2024-03-06 21:51:11,935 ERROR Internal Server Error: /news/ E:\projects\np-django\venv\Lib\site-packages\django\utils\log.py (<class 'ValueError'>, ValueError('localtime() cannot be applied to a naive datetime'), <traceback object at 0x0000020F91A71AC0>)
Traceback (most recent call last):
  File "E:\projects\np-django\venv\Lib\site-packages\django\core\handlers\exception.py", line 55, in inner
    response = get_response(request)
               ^^^^^^^^^^^^^^^^^^^^^
  File "E:\projects\np-django\venv\Lib\site-packages\django\core\handlers\base.py", line 197, in _get_response
    response = wrapped_callback(request, *callback_args, **callback_kwargs)
               ^^^^^^^^^^^^^^^^^^^^^^^^^^^^^^^^^^^^^^^^^^^^^^^^^^^^^^^^^^^^
  File "E:\projects\np-django\venv\Lib\site-packages\django\views\generic\base.py", line 104, in view
    return self.dispatch(request, *args, **kwargs)
           ^^^^^^^^^^^^^^^^^^^^^^^^^^^^^^^^^^^^^^^
  File "E:\projects\np-django\venv\Lib\site-packages\django\views\generic\base.py", line 143, in dispatch
    return handler(request, *args, **kwargs)
           ^^^^^^^^^^^^^^^^^^^^^^^^^^^^^^^^^
  File "E:\projects\np-django\NewsPaper\news\views.py", line 64, in get
    'current_time': timezone.localtime(timezone.now()),
                    ^^^^^^^^^^^^^^^^^^^^^^^^^^^^^^^^^^
  File "E:\projects\np-django\venv\Lib\site-packages\django\utils\timezone.py", line 183, in localtime
    raise ValueError("localtime() cannot be applied to a naive datetime")
ValueError: localtime() cannot be applied to a naive datetime
2024-03-06 21:51:11,940 ERROR "GET /news/ HTTP/1.1" 500 82509 E:\projects\np-django\venv\Lib\site-packages\django\core\servers\basehttp.py None
2024-03-06 21:52:07,841 ERROR Internal Server Error: /news/ E:\projects\np-django\venv\Lib\site-packages\django\utils\log.py (<class 'ValueError'>, ValueError('localtime() cannot be applied to a naive datetime'), <traceback object at 0x0000020F92B059C0>)
Traceback (most recent call last):
  File "E:\projects\np-django\venv\Lib\site-packages\django\core\handlers\exception.py", line 55, in inner
    response = get_response(request)
               ^^^^^^^^^^^^^^^^^^^^^
  File "E:\projects\np-django\venv\Lib\site-packages\django\core\handlers\base.py", line 197, in _get_response
    response = wrapped_callback(request, *callback_args, **callback_kwargs)
               ^^^^^^^^^^^^^^^^^^^^^^^^^^^^^^^^^^^^^^^^^^^^^^^^^^^^^^^^^^^^
  File "E:\projects\np-django\venv\Lib\site-packages\django\views\generic\base.py", line 104, in view
    return self.dispatch(request, *args, **kwargs)
           ^^^^^^^^^^^^^^^^^^^^^^^^^^^^^^^^^^^^^^^
  File "E:\projects\np-django\venv\Lib\site-packages\django\views\generic\base.py", line 143, in dispatch
    return handler(request, *args, **kwargs)
           ^^^^^^^^^^^^^^^^^^^^^^^^^^^^^^^^^
  File "E:\projects\np-django\NewsPaper\news\views.py", line 64, in get
    'current_time': timezone.localtime(timezone.now()),
                    ^^^^^^^^^^^^^^^^^^^^^^^^^^^^^^^^^^
  File "E:\projects\np-django\venv\Lib\site-packages\django\utils\timezone.py", line 183, in localtime
    raise ValueError("localtime() cannot be applied to a naive datetime")
ValueError: localtime() cannot be applied to a naive datetime
2024-03-06 21:52:07,841 ERROR "GET /news/ HTTP/1.1" 500 82508 E:\projects\np-django\venv\Lib\site-packages\django\core\servers\basehttp.py None
2024-03-06 21:52:38,350 ERROR Internal Server Error: /news/ E:\projects\np-django\venv\Lib\site-packages\django\utils\log.py (<class 'ValueError'>, ValueError('localtime() cannot be applied to a naive datetime'), <traceback object at 0x0000020F91A771C0>)
Traceback (most recent call last):
  File "E:\projects\np-django\venv\Lib\site-packages\django\core\handlers\exception.py", line 55, in inner
    response = get_response(request)
               ^^^^^^^^^^^^^^^^^^^^^
  File "E:\projects\np-django\venv\Lib\site-packages\django\core\handlers\base.py", line 197, in _get_response
    response = wrapped_callback(request, *callback_args, **callback_kwargs)
               ^^^^^^^^^^^^^^^^^^^^^^^^^^^^^^^^^^^^^^^^^^^^^^^^^^^^^^^^^^^^
  File "E:\projects\np-django\venv\Lib\site-packages\django\views\generic\base.py", line 104, in view
    return self.dispatch(request, *args, **kwargs)
           ^^^^^^^^^^^^^^^^^^^^^^^^^^^^^^^^^^^^^^^
  File "E:\projects\np-django\venv\Lib\site-packages\django\views\generic\base.py", line 143, in dispatch
    return handler(request, *args, **kwargs)
           ^^^^^^^^^^^^^^^^^^^^^^^^^^^^^^^^^
  File "E:\projects\np-django\NewsPaper\news\views.py", line 64, in get
    'current_time': timezone.localtime(timezone.now()),
                    ^^^^^^^^^^^^^^^^^^^^^^^^^^^^^^^^^^
  File "E:\projects\np-django\venv\Lib\site-packages\django\utils\timezone.py", line 183, in localtime
    raise ValueError("localtime() cannot be applied to a naive datetime")
ValueError: localtime() cannot be applied to a naive datetime
2024-03-06 21:52:38,350 ERROR "GET /news/ HTTP/1.1" 500 82509 E:\projects\np-django\venv\Lib\site-packages\django\core\servers\basehttp.py None
2024-03-06 22:01:58,398 ERROR Internal Server Error: /news/ E:\projects\np-django\venv\Lib\site-packages\django\utils\log.py (<class 'django.urls.exceptions.NoReverseMatch'>, NoReverseMatch("Reverse for '' not found. '' is not a valid view function or pattern name."), <traceback object at 0x00000263E8B77180>)
Traceback (most recent call last):
  File "E:\projects\np-django\venv\Lib\site-packages\django\core\handlers\exception.py", line 55, in inner
    response = get_response(request)
               ^^^^^^^^^^^^^^^^^^^^^
  File "E:\projects\np-django\venv\Lib\site-packages\django\core\handlers\base.py", line 197, in _get_response
    response = wrapped_callback(request, *callback_args, **callback_kwargs)
               ^^^^^^^^^^^^^^^^^^^^^^^^^^^^^^^^^^^^^^^^^^^^^^^^^^^^^^^^^^^^
  File "E:\projects\np-django\venv\Lib\site-packages\django\views\generic\base.py", line 104, in view
    return self.dispatch(request, *args, **kwargs)
           ^^^^^^^^^^^^^^^^^^^^^^^^^^^^^^^^^^^^^^^
  File "E:\projects\np-django\venv\Lib\site-packages\django\views\generic\base.py", line 143, in dispatch
    return handler(request, *args, **kwargs)
           ^^^^^^^^^^^^^^^^^^^^^^^^^^^^^^^^^
  File "E:\projects\np-django\NewsPaper\news\views.py", line 75, in post
    return redirect('')
           ^^^^^^^^^^^^
  File "E:\projects\np-django\venv\Lib\site-packages\django\shortcuts.py", line 48, in redirect
    return redirect_class(resolve_url(to, *args, **kwargs))
                          ^^^^^^^^^^^^^^^^^^^^^^^^^^^^^^^^
  File "E:\projects\np-django\venv\Lib\site-packages\django\shortcuts.py", line 179, in resolve_url
    return reverse(to, args=args, kwargs=kwargs)
           ^^^^^^^^^^^^^^^^^^^^^^^^^^^^^^^^^^^^^
  File "E:\projects\np-django\venv\Lib\site-packages\django\urls\base.py", line 88, in reverse
    return resolver._reverse_with_prefix(view, prefix, *args, **kwargs)
           ^^^^^^^^^^^^^^^^^^^^^^^^^^^^^^^^^^^^^^^^^^^^^^^^^^^^^^^^^^^^
  File "E:\projects\np-django\venv\Lib\site-packages\django\urls\resolvers.py", line 848, in _reverse_with_prefix
    raise NoReverseMatch(msg)
django.urls.exceptions.NoReverseMatch: Reverse for '' not found. '' is not a valid view function or pattern name.
2024-03-06 22:01:58,403 ERROR "POST /news/ HTTP/1.1" 500 97660 E:\projects\np-django\venv\Lib\site-packages\django\core\servers\basehttp.py None
2024-03-11 19:23:21,156 ERROR Internal Server Error: /swagger-ui/ E:\projects\np-django\venv\Lib\site-packages\django\utils\log.py (<class 'django.template.exceptions.TemplateDoesNotExist'>, TemplateDoesNotExist('swagger-ui.html'), <traceback object at 0x0000020E6D095BC0>)
Traceback (most recent call last):
  File "E:\projects\np-django\venv\Lib\site-packages\django\core\handlers\exception.py", line 55, in inner
    response = get_response(request)
               ^^^^^^^^^^^^^^^^^^^^^
  File "E:\projects\np-django\venv\Lib\site-packages\django\core\handlers\base.py", line 220, in _get_response
    response = response.render()
               ^^^^^^^^^^^^^^^^^
  File "E:\projects\np-django\venv\Lib\site-packages\django\template\response.py", line 114, in render
    self.content = self.rendered_content
                   ^^^^^^^^^^^^^^^^^^^^^
  File "E:\projects\np-django\venv\Lib\site-packages\django\template\response.py", line 90, in rendered_content
    template = self.resolve_template(self.template_name)
               ^^^^^^^^^^^^^^^^^^^^^^^^^^^^^^^^^^^^^^^^^
  File "E:\projects\np-django\venv\Lib\site-packages\django\template\response.py", line 72, in resolve_template
    return select_template(template, using=self.using)
           ^^^^^^^^^^^^^^^^^^^^^^^^^^^^^^^^^^^^^^^^^^^
  File "E:\projects\np-django\venv\Lib\site-packages\django\template\loader.py", line 47, in select_template
    raise TemplateDoesNotExist(", ".join(template_name_list), chain=chain)
django.template.exceptions.TemplateDoesNotExist: swagger-ui.html
2024-03-11 19:23:21,159 ERROR "GET /swagger-ui/ HTTP/1.1" 500 83942 E:\projects\np-django\venv\Lib\site-packages\django\core\servers\basehttp.py None
2024-03-11 21:01:49,852 ERROR Internal Server Error: /api/posts/ E:\projects\np-django\venv\Lib\site-packages\django\utils\log.py (<class 'NameError'>, NameError("name 'IsAuthenticated' is not defined"), <traceback object at 0x000002A4FEC0AF00>)
Traceback (most recent call last):
  File "E:\projects\np-django\venv\Lib\site-packages\django\core\handlers\exception.py", line 55, in inner
    response = get_response(request)
               ^^^^^^^^^^^^^^^^^^^^^
  File "E:\projects\np-django\venv\Lib\site-packages\django\core\handlers\base.py", line 197, in _get_response
    response = wrapped_callback(request, *callback_args, **callback_kwargs)
               ^^^^^^^^^^^^^^^^^^^^^^^^^^^^^^^^^^^^^^^^^^^^^^^^^^^^^^^^^^^^
  File "E:\projects\np-django\venv\Lib\site-packages\django\views\decorators\csrf.py", line 65, in _view_wrapper
    return view_func(request, *args, **kwargs)
           ^^^^^^^^^^^^^^^^^^^^^^^^^^^^^^^^^^^
  File "E:\projects\np-django\venv\Lib\site-packages\rest_framework\viewsets.py", line 125, in view
    return self.dispatch(request, *args, **kwargs)
           ^^^^^^^^^^^^^^^^^^^^^^^^^^^^^^^^^^^^^^^
  File "E:\projects\np-django\venv\Lib\site-packages\rest_framework\views.py", line 509, in dispatch
    response = self.handle_exception(exc)
               ^^^^^^^^^^^^^^^^^^^^^^^^^^
  File "E:\projects\np-django\venv\Lib\site-packages\rest_framework\views.py", line 469, in handle_exception
    self.raise_uncaught_exception(exc)
  File "E:\projects\np-django\venv\Lib\site-packages\rest_framework\views.py", line 480, in raise_uncaught_exception
    raise exc
  File "E:\projects\np-django\venv\Lib\site-packages\rest_framework\views.py", line 497, in dispatch
    self.initial(request, *args, **kwargs)
  File "E:\projects\np-django\venv\Lib\site-packages\rest_framework\views.py", line 415, in initial
    self.check_permissions(request)
  File "E:\projects\np-django\venv\Lib\site-packages\rest_framework\views.py", line 331, in check_permissions
    for permission in self.get_permissions():
                      ^^^^^^^^^^^^^^^^^^^^^^
  File "E:\projects\np-django\NewsPaper\news\views.py", line 326, in get_permissions
    return [IsAuthenticated()]
            ^^^^^^^^^^^^^^^
NameError: name 'IsAuthenticated' is not defined
2024-03-11 21:01:49,857 ERROR "GET /api/posts/ HTTP/1.1" 500 104123 E:\projects\np-django\venv\Lib\site-packages\django\core\servers\basehttp.py None
